Workbook

Sheet 개요
A1: 기능 명세 · API 명세 (새 탭 북마크 도구)
A3: 기준 문서 | B3: service-plan.md, 4주차 강의 자료(EARS), 확정 디자인 시안(Figma Make, 10월 6일), category-definitions.md(카테고리 정의와 분류표, 10월 7일)
A4: 작성일 · 판 | B4: 2026-10-07 · v13 (v2: 읽어서 점검 / v3: 시험용 확장 프로그램 실행 / v4: 프로토타입 구현·검증 / v5: 남은 결정 8개 확정 / v6·v7: 상세 도메인 21개와 담당(안) 열, 파일별 역할 시트 / v8: 전체 문서 대조. 권한 요청 위치를 render.js로, store.js 함수 3줄 추가 / v9: 북마크바를 정리 대상에 포함, 새 폴더를 북마크바 맨 뒤에 생성, 요즘 쓰는 북마크 보호, 잊고 있던 북마크 8개 상한과 "연 기록 없음", 우선순위를 P1·P2·P3로 변경, 확정 디자인 시안 반영 / v10: 프로토타입 코드를 쓰지 않고 새로 작성, 화면 파일을 render.js + view/ 아래 4개로 나눔, 코드를 extension/ 폴더로 분리 / v11: 공통 화면 파일 ui.js 추가(N44~N46), 분류표 형태와 분류하지 않는 사이트(F05-01, N17), measure 출력 이름(N18), 팝업은 <dialog>(F12-04), 문서 이름을 영어로 변경 / v12: 5주차 활동지를 저장소에서 빼고 '관련 태스크' 열을 '관련 이슈'로 바꿈. GitHub 이슈 #1~#19 = 파일 19개('파일별 역할' 시트의 이슈 열), #22~#24 = 우선순위별 요구사항 확인 목록. N06의 출력과 C19의 주의에서 서로 어긋나던 문장을 맞춤. 크롬 가져오기 폴더의 바로 아래 북마크를 정리 대상에 포함(F05-04, N19) / v13: 화면 연결 방식 확정. 내 폴더 줄을 그리는 showFolders 추가(N41), 다른 화면 파일의 동작은 render.js가 동작 묶음(actions)으로 넘김(N30, N31, N42), showOrganizeDialog가 폴더 계획을 입력으로 받음, 화면 칸 이름은 file-structure.md 12번)
A5: 시트 구성 | B5: 기능 명세 / API_크롬 / API_내부 함수 / 참고_저장 항목 / 파일별 역할. 각 시트의 첫 열은 도메인(역할)이며, 둘째 열은 담당(안). 이 시트 아래쪽에 도메인별·담당별 요약이, '파일별 역할' 시트에 파일마다 하는 일이 있음
A6: 요구사항 문장 | B6: 4주차 EARS 형식. WHEN(사건)·WHILE(상태)·IF…THEN(예외) + THE(주체) + SHALL(동작·결과). 정상 경로와 예외 경로를 함께 적음
A7: ID 규칙 | B7: 기능 F01~F17 / 요구사항 F01-01 / 크롬 API C01~ / 내부 함수 N01~ / GitHub 이슈 #1~#19 = 파일 19개, #22~#24 = P1·P2·P3 확인 목록 (v12)
A8: 비고의 '제안' | B8: 계획 문서에 없어서 임시로 채운 내용. 팀에서 확정하거나 고쳐야 함 (노란색 칸)
A9: 비고의 '확인 필요' | B9: 팀 결정이나 개발 첫 주 실험이 있어야 정해지는 내용 (노란색 칸)
A10: 비고의 '실행 확인' | B10: 시험용 확장 프로그램을 Chromium 141에서 실제로 돌려 확인한 내용 (초록색 칸). '수정'·'추가'는 점검으로 고친 줄
A11: 수정 방법 | B11: 요구사항을 바꿀 때는 '기능 명세' 시트의 G열(요구사항) 문장을 고치고, 관련된 API 시트의 '관련 기능' 열을 함께 확인
A12: 우선순위 | B12: P1: 11주 중간 데모에서 끝까지 동작 / P2: 15주 최종 데모까지 / P3: 시간이 남으면. 요구사항마다 '기능 명세' 시트 F열에 적음 (v9, Must·Should에서 변경)
A14: 기능 ID | B14: 기능명 | C14: 우선순위 | D14: 관련 이슈 | E14: 요구사항 수 | F14: 그중 예외 경로 | G14: 제안·확인 필요 수
A15: F01 | B15: 크롬 북마크 자동 동기화 | C15: P1 | D15: #22 | E15: =COUNTIF('기능 명세'!$D:$D,A15) -> 7 | F15: =COUNTIFS('기능 명세'!$D:$D,A15,'기능 명세'!$H:$H,"예외") -> 3 | G15: =COUNTIFS('기능 명세'!$D:$D,A15,'기능 명세'!$N:$N,"제안*")+COUNTIFS('기능 명세'!$D:$D,A15,'기능 명세'!$N:$N,"확인 필요*") -> 3
A16: F02 | B16: 앱 형태 북마크 | C16: P1 | D16: #22 | E16: =COUNTIF('기능 명세'!$D:$D,A16) -> 5 | F16: =COUNTIFS('기능 명세'!$D:$D,A16,'기능 명세'!$H:$H,"예외") -> 3 | G16: =COUNTIFS('기능 명세'!$D:$D,A16,'기능 명세'!$N:$N,"제안*")+COUNTIFS('기능 명세'!$D:$D,A16,'기능 명세'!$N:$N,"확인 필요*") -> 2
A17: F03 | B17: 앱 폴더 | C17: P1 · P2 | D17: #22, #23 | E17: =COUNTIF('기능 명세'!$D:$D,A17) -> 8 | F17: =COUNTIFS('기능 명세'!$D:$D,A17,'기능 명세'!$H:$H,"예외") -> 2 | G17: =COUNTIFS('기능 명세'!$D:$D,A17,'기능 명세'!$N:$N,"제안*")+COUNTIFS('기능 명세'!$D:$D,A17,'기능 명세'!$N:$N,"확인 필요*") -> 3
A18: F04 | B18: 잊고 있던 북마크 (재발견) | C18: P1 · P2 | D18: #22, #23 | E18: =COUNTIF('기능 명세'!$D:$D,A18) -> 12 | F18: =COUNTIFS('기능 명세'!$D:$D,A18,'기능 명세'!$H:$H,"예외") -> 2 | G18: =COUNTIFS('기능 명세'!$D:$D,A18,'기능 명세'!$N:$N,"제안*")+COUNTIFS('기능 명세'!$D:$D,A18,'기능 명세'!$N:$N,"확인 필요*") -> 0
A19: F05 | B19: 분류와 폴더 계획 | C19: P1 | D19: #22 | E19: =COUNTIF('기능 명세'!$D:$D,A19) -> 9 | F19: =COUNTIFS('기능 명세'!$D:$D,A19,'기능 명세'!$H:$H,"예외") -> 2 | G19: =COUNTIFS('기능 명세'!$D:$D,A19,'기능 명세'!$N:$N,"제안*")+COUNTIFS('기능 명세'!$D:$D,A19,'기능 명세'!$N:$N,"확인 필요*") -> 1
A20: F06 | B20: 첫 정리 카드 + 자세히 보기 | C20: P1 · P2 | D20: #22, #23 | E20: =COUNTIF('기능 명세'!$D:$D,A20) -> 7 | F20: =COUNTIFS('기능 명세'!$D:$D,A20,'기능 명세'!$H:$H,"예외") -> 1 | G20: =COUNTIFS('기능 명세'!$D:$D,A20,'기능 명세'!$N:$N,"제안*")+COUNTIFS('기능 명세'!$D:$D,A20,'기능 명세'!$N:$N,"확인 필요*") -> 0
A21: F07 | B21: 정리 적용 + 직접 옮김 처리 | C21: P1 · P2 | D21: #22, #23 | E21: =COUNTIF('기능 명세'!$D:$D,A21) -> 9 | F21: =COUNTIFS('기능 명세'!$D:$D,A21,'기능 명세'!$H:$H,"예외") -> 2 | G21: =COUNTIFS('기능 명세'!$D:$D,A21,'기능 명세'!$N:$N,"제안*")+COUNTIFS('기능 명세'!$D:$D,A21,'기능 명세'!$N:$N,"확인 필요*") -> 1
A22: F08 | B22: 고정됨 (독) | C22: P2 | D22: #23 | E22: =COUNTIF('기능 명세'!$D:$D,A22) -> 6 | F22: =COUNTIFS('기능 명세'!$D:$D,A22,'기능 명세'!$H:$H,"예외") -> 2 | G22: =COUNTIFS('기능 명세'!$D:$D,A22,'기능 명세'!$N:$N,"제안*")+COUNTIFS('기능 명세'!$D:$D,A22,'기능 명세'!$N:$N,"확인 필요*") -> 0
A23: F09 | B23: 폴더를 못 만들 때 고정 제안 | C23: P2 | D23: #23 | E23: =COUNTIF('기능 명세'!$D:$D,A23) -> 9 | F23: =COUNTIFS('기능 명세'!$D:$D,A23,'기능 명세'!$H:$H,"예외") -> 2 | G23: =COUNTIFS('기능 명세'!$D:$D,A23,'기능 명세'!$N:$N,"제안*")+COUNTIFS('기능 명세'!$D:$D,A23,'기능 명세'!$N:$N,"확인 필요*") -> 3
A24: F10 | B24: 새 북마크 정리 ([정리하기]) | C24: P2 | D24: #23 | E24: =COUNTIF('기능 명세'!$D:$D,A24) -> 9 | F24: =COUNTIFS('기능 명세'!$D:$D,A24,'기능 명세'!$H:$H,"예외") -> 2 | G24: =COUNTIFS('기능 명세'!$D:$D,A24,'기능 명세'!$N:$N,"제안*")+COUNTIFS('기능 명세'!$D:$D,A24,'기능 명세'!$N:$N,"확인 필요*") -> 1
A25: F11 | B25: 웹 검색창 (크롬 검색 유지) | C25: P1 | D25: #22 | E25: =COUNTIF('기능 명세'!$D:$D,A25) -> 5 | F25: =COUNTIFS('기능 명세'!$D:$D,A25,'기능 명세'!$H:$H,"예외") -> 1 | G25: =COUNTIFS('기능 명세'!$D:$D,A25,'기능 명세'!$N:$N,"제안*")+COUNTIFS('기능 명세'!$D:$D,A25,'기능 명세'!$N:$N,"확인 필요*") -> 1
A26: F12 | B26: 새 탭 첫 화면 배치 + 반응형 | C26: P1 | D26: #22 | E26: =COUNTIF('기능 명세'!$D:$D,A26) -> 4 | F26: =COUNTIFS('기능 명세'!$D:$D,A26,'기능 명세'!$H:$H,"예외") -> 0 | G26: =COUNTIFS('기능 명세'!$D:$D,A26,'기능 명세'!$N:$N,"제안*")+COUNTIFS('기능 명세'!$D:$D,A26,'기능 명세'!$N:$N,"확인 필요*") -> 1
... A31: F17 | B31: 드래그 이동 | C31: P3 | D31: #24 | E31: =COUNTIF('기능 명세'!$D:$D,A31) -> 3 | F31: =COUNTIFS('기능 명세'!$D:$D,A31,'기능 명세'!$H:$H,"예외") -> 1 | G31: =COUNTIFS('기능 명세'!$D:$D,A31,'기능 명세'!$N:$N,"제안*")+COUNTIFS('기능 명세'!$D:$D,A31,'기능 명세'!$N:$N,"확인 필요*") -> 0
A32: 합계 | E32: =SUM(E15:E31) -> 117 | F32: =SUM(F15:F31) -> 34 | G32: =SUM(G15:G31) -> 22
A34: 도메인별 요약 (상세 도메인 21개)
A35: 도메인 | B35: 하는 일 | C35: 담당(안) | D35: 관련 파일 | E35: 요구사항 수 | F35: 내부 함수 수 | G35: 크롬 API 수
A36: 확장 프로그램 설정 | B36: 권한, 새 탭 바꾸기, 서비스 워커 등록 | C36: 팀원 A | D36: manifest.json | E36: =COUNTIF('기능 명세'!$A:$A,A36) -> 0 | F36: =COUNTIF('API_내부 함수'!$A:$A,A36) -> 0 | G36: =COUNTIF(API_크롬!$A:$A,A36) -> 3
A37: 북마크 동기화 | B37: 크롬 북마크를 읽고, 바뀌면 화면에 자동 반영 | C37: 팀원 A | D37: bookmarks.js | E37: =COUNTIF('기능 명세'!$A:$A,A37) -> 6 | F37: =COUNTIF('API_내부 함수'!$A:$A,A37) -> 1 | G37: =COUNTIF(API_크롬!$A:$A,A37) -> 4
A38: 저장 항목 | B38: 우리가 따로 기억하는 정보(chrome.storage.local)를 읽고 쓰기 | C38: 팀원 A | D38: background.js, store.js | E38: =COUNTIF('기능 명세'!$A:$A,A38) -> 1 | F38: =COUNTIF('API_내부 함수'!$A:$A,A38) -> 4 | G38: =COUNTIF(API_크롬!$A:$A,A38) -> 3
A39: 앱 표시·열기 | B39: 북마크를 앱 아이콘으로 보여 주고, 눌렀을 때 열기 | C39: 팀원 D | D39: bookmarks.js, ui.js | E39: =COUNTIF('기능 명세'!$A:$A,A39) -> 5 | F39: =COUNTIF('API_내부 함수'!$A:$A,A39) -> 3 | G39: =COUNTIF(API_크롬!$A:$A,A39) -> 2
A40: 앱 폴더 | B40: 폴더 열기·만들기·이름 바꾸기·삭제 | C40: 팀원 C | D40: bookmarks.js, view/folders.js | E40: =COUNTIF('기능 명세'!$A:$A,A40) -> 8 | F40: =COUNTIF('API_내부 함수'!$A:$A,A40) -> 4 | G40: =COUNTIF(API_크롬!$A:$A,A40) -> 3
A41: 분류 규칙 | B41: 북마크를 분류표·주소 끝·제목 키워드로 카테고리에 넣기 | C41: 팀원 B | D41: classify.js | E41: =COUNTIF('기능 명세'!$A:$A,A41) -> 4 | F41: =COUNTIF('API_내부 함수'!$A:$A,A41) -> 2 | G41: =COUNTIF(API_크롬!$A:$A,A41) -> 0
A42: 폴더 계획 | B42: 정리 대상을 고르고, 만들 폴더와 넣을 북마크를 정하기 | C42: 팀원 C | D42: plan.js | E42: =COUNTIF('기능 명세'!$A:$A,A42) -> 5 | F42: =COUNTIF('API_내부 함수'!$A:$A,A42) -> 2 | G42: =COUNTIF(API_크롬!$A:$A,A42) -> 0
A43: 정리 카드 | B43: 첫 정리 제안 카드와 자세히 보기 | C43: 팀원 D | D43: store.js, view/cards.js | E43: =COUNTIF('기능 명세'!$A:$A,A43) -> 7 | F43: =COUNTIF('API_내부 함수'!$A:$A,A43) -> 2 | G43: =COUNTIF(API_크롬!$A:$A,A43) -> 0
A44: 정리 적용 | B44: 계획대로 폴더를 만들고 북마크를 실제로 옮기기 | C44: 팀원 A | D44: bookmarks.js, organize.js | E44: =COUNTIF('기능 명세'!$A:$A,A44) -> 6 | F44: =COUNTIF('API_내부 함수'!$A:$A,A44) -> 2 | G44: =COUNTIF(API_크롬!$A:$A,A44) -> 1
A45: 직접 옮김 감지 | B45: 사용자가 직접 옮긴 것과 우리 정리가 옮긴 것을 구별해 기록 | C45: 팀원 B | D45: background.js, store.js | E45: =COUNTIF('기능 명세'!$A:$A,A45) -> 3 | F45: =COUNTIF('API_내부 함수'!$A:$A,A45) -> 3 | G45: =COUNTIF(API_크롬!$A:$A,A45) -> 1
A46: 되돌리기·정리 기록 | B46: 정리 내역을 보여 주고 원래 위치로 되돌리기 | C46: 팀원 A | D46: organize.js, store.js, view/history.js | E46: =COUNTIF('기능 명세'!$A:$A,A46) -> 10 | F46: =COUNTIF('API_내부 함수'!$A:$A,A46) -> 3 | G46: =COUNTIF(API_크롬!$A:$A,A46) -> 0
A47: 새 북마크 정리 | B47: 새로 저장된 북마크를 기록하고 추천 폴더로 정리 | C47: 팀원 B | D47: background.js, classify.js, plan.js, store.js | E47: =COUNTIF('기능 명세'!$A:$A,A47) -> 9 | F47: =COUNTIF('API_내부 함수'!$A:$A,A47) -> 5 | G47: =COUNTIF(API_크롬!$A:$A,A47) -> 1
...

Sheet 기능 명세
A1: 도메인 | B1: 담당(안) | C1: 협업 담당 | D1: 기능 ID | E1: 기능명 | F1: 우선순위 | G1: 요구사항 ID | H1: 유형 | I1: EARS 패턴 | J1: 요구사항 (EARS) | K1: 화면 | L1: 관련 이슈 | M1: 근거 (계획 문서 절) | N1: 비고
A2: 북마크 동기화 | B2: 팀원 A | C2: 팀원 D | D2: F01 | E2: 크롬 북마크 자동 동기화 | F2: P1 | G2: F01-01 | H2: 정상 | I2: Event-driven | J2: WHEN 사용자가 새 탭을 열면 THE 시스템은 SHALL 크롬 북마크 전체를 읽어 화면에 표시하고, 표시한 북마크 개수는 크롬 북마크 관리자의 개수와 같다. | K2: 새 탭 메인 | L2: #22 | M2: 2-1, 3-1
A3: 북마크 동기화 | B3: 팀원 A | C3: 팀원 D | D3: F01 | E3: 크롬 북마크 자동 동기화 | F3: P1 | G3: F01-02 | H3: 정상 | I3: Event-driven | J3: WHEN 크롬에서 북마크가 추가·수정·삭제·이동되면 THE 새 탭 화면은 SHALL 사용자가 새로고침하지 않아도 그 변경을 화면에 반영한다. | K3: 새 탭 메인 | L3: #22 | M3: 2-1, 3-1
A4: 북마크 동기화 | B4: 팀원 A | D4: F01 | E4: 크롬 북마크 자동 동기화 | F4: P1 | G4: F01-03 | H4: 정상 | I4: Ubiquitous | J4: THE 시스템은 SHALL 북마크의 제목과 주소를 확장 프로그램 밖(서버, 외부 API)으로 전송하지 않는다. | K4: 화면 없음 | L4: #22 | M4: 2-1, 3-1
A5: 북마크 동기화 | B5: 팀원 A | D5: F01 | E5: 크롬 북마크 자동 동기화 | F5: P1 | G5: F01-04 | H5: 정상 | I5: Ubiquitous | J5: THE 시스템은 SHALL 북마크바·기타 북마크·모바일 북마크를 폴더 ID가 아닌 folderType 값으로 구별한다. | K5: 화면 없음 | L5: #22 | M5: 2-1, 3-1
A6: 북마크 동기화 | B6: 팀원 A | C6: 팀원 D | D6: F01 | E6: 크롬 북마크 자동 동기화 | F6: P1 | G6: F01-05 | H6: 예외 | I6: Unwanted | J6: IF 크롬에 북마크가 하나도 없으면 THEN THE 새 탭 화면은 SHALL "아직 북마크가 없어요. 주소창의 별 버튼으로 저장해 보세요"를 표시한다. | K6: 새 탭 메인 | L6: #22 | M6: 2-1, 3-1 | N6: 제안: 문구는 계획 문서에 없음
A7: 저장 항목 | B7: 팀원 A | C7: 팀원 B | D7: F01 | E7: 크롬 북마크 자동 동기화 | F7: P1 | G7: F01-06 | H7: 예외 | I7: Unwanted | J7: IF 북마크가 크롬에서 삭제되면 THEN THE 시스템은 SHALL 저장 항목에서 그 북마크 ID를 지운다. 서비스 워커는 manualMoves·newBookmarks에서 바로 지우고, 새 탭은 열릴 때 pinned·lastOpenedByUs·dismissed·handledNew에서 지운다. | K7: 화면 없음 | L7: #22 | M7: 2-1, 3-1 | N7: 제안: 한 저장 항목은 한쪽만 쓴다는 규칙에 맞춘 정리 방식
A8: 북마크 동기화 | B8: 팀원 A | C8: 팀원 B | D8: F01 | E8: 크롬 북마크 자동 동기화 | F8: P1 | G8: F01-07 | H8: 예외 | I8: Unwanted | J8: IF 크롬이 북마크 가져오기(import)를 진행 중이면 THEN THE 서비스 워커는 SHALL 가져오기가 끝날 때까지 새 북마크 기록을 멈추고, 끝난 뒤 한 번만 다시 읽는다. | K8: 화면 없음 | L8: #22 | M8: 2-1, 3-1 | N8: 제안: 크롬 문서가 권장하는 처리
A9: 앱 표시·열기 | B9: 팀원 D | D9: F02 | E9: 앱 형태 북마크 | F9: P1 | G9: F02-01 | H9: 정상 | I9: Ubiquitous | J9: THE 새 탭 화면은 SHALL 북마크 하나를 사이트 아이콘(색 타일 위의 파비콘)과 제목이 있는 앱 하나로 표시한다. | K9: 새 탭 메인 | L9: #22 | M9: 2-2, 3-2 | N9: 추가(v11): 앱 아이콘은 모든 화면에서 ui.js의 appIcon으로 그린다
A10: 앱 표시·열기 | B10: 팀원 D | C10: 팀원 A | D10: F02 | E10: 앱 형태 북마크 | F10: P1 | G10: F02-02 | H10: 정상 | I10: Event-driven | J10: WHEN 사용자가 앱을 클릭하면 THE 시스템은 SHALL 연 시각을 lastOpenedByUs에 기록한 뒤 현재 탭에서 그 북마크의 주소를 연다. | K10: 새 탭 메인 | L10: #22 | M10: 2-2, 3-2 | N10: 제안: 클릭은 현재 탭, 우클릭 메뉴는 새 탭. 실행 확인(v3): 기록을 기다리지 않고 바로 이동해도 기록은 남았음. 순서를 지키는 것은 안전을 위한 것
A11: 앱 표시·열기 | B11: 팀원 D | D11: F02 | E11: 앱 형태 북마크 | F11: P1 | G11: F02-03 | H11: 예외 | I11: Unwanted | J11: IF 사이트의 파비콘이 없으면 THEN THE 새 탭 화면은 SHALL 제목의 첫 글자를 아이콘으로 표시한다. | K11: 새 탭 메인 | L11: #22 | M11: 2-2, 3-2 | N11: 실행 확인(v3): 파비콘이 없는 주소는 모두 똑같은 기본 그림(같은 바이트)이 돌아옴. 방문한 적 없는 주소의 결과를 기준으로 삼아 비교하면 판별됨. 파비콘은 사이트가 아니라 페이지 주소 단위로 저장돼 있으므로, 없으면 사이트 첫 페이지 주소로 한 번 더 찾고 그래도 없으면 첫 글자
A12: 앱 표시·열기 | B12: 팀원 D | D12: F02 | E12: 앱 형태 북마크 | F12: P1 | G12: F02-04 | H12: 예외 | I12: Unwanted | J12: IF 북마크 주소가 chrome:// 또는 file://로 시작하면 THEN THE 시스템은 SHALL 일반 링크 대신 chrome.tabs API로 그 주소를 연다. | K12: 새 탭 메인 | L12: #22 | M12: 2-2, 3-2
A13: 앱 표시·열기 | B13: 팀원 D | D13: F02 | E13: 앱 형태 북마크 | F13: P1 | G13: F02-05 | H13: 예외 | I13: Unwanted | J13: IF 북마크 주소가 javascript:로 시작하면 THEN THE 시스템은 SHALL 실행하지 않고 "이 북마크는 새 탭에서 실행할 수 없어요"를 표시한다. | K13: 새 탭 메인 | L13: #22 | M13: 2-2, 3-2 | N13: 제안: 북마클릿은 확장 프로그램 페이지에서 실행 불가
A14: 앱 폴더 | B14: 팀원 C | C14: 팀원 D | D14: F03 | E14: 앱 폴더 | F14: P1 | G14: F03-01 | H14: 정상 | I14: Ubiquitous | J14: THE 새 탭 화면은 SHALL 크롬 북마크 폴더(사용자가 원래 만든 폴더 포함)를 안에 든 앱의 미리보기 칸·이름·개수가 있는 앱 폴더로 표시한다. | K14: 새 탭 메인 | L14: #22 | M14: 2-2, 3-2
A15: 앱 폴더 | B15: 팀원 C | C15: 팀원 D | D15: F03 | E15: 앱 폴더 | F15: P1 | G15: F03-02 | H15: 정상 | I15: Ubiquitous | J15: THE 새 탭 화면은 SHALL 북마크바·기타 북마크·모바일 북마크 자체는 앱 폴더로 표시하지 않고, 그 안의 폴더와 북마크를 표시한다. | K15: 새 탭 메인 | L15: #22 | M15: 2-2, 3-2 | N15: 제안: 루트 폴더 표시 방식
A16: 앱 폴더 | B16: 팀원 C | C16: 팀원 D | D16: F03 | E16: 앱 폴더 | F16: P1 | G16: F03-03 | H16: 정상 | I16: Event-driven | J16: WHEN 사용자가 앱 폴더를 클릭하면 THE 새 탭 화면은 SHALL 메인 화면 위에 팝업을 열어 그 폴더 안의 앱을 표시한다. | K16: 새 탭 메인 | L16: #22 | M16: 2-2, 3-2
A17: 앱 폴더 | B17: 팀원 C | C17: 팀원 D | D17: F03 | E17: 앱 폴더 | F17: P2 | G17: F03-04 | H17: 정상 | I17: Event-driven | J17: WHEN 사용자가 폴더 만들기에서 이름을 입력하고 확인하면 THE 시스템은 SHALL 북마크바 맨 뒤에 그 이름의 크롬 북마크 폴더를 만들고 앱 폴더로 표시한다. | K17: 새 탭 메인 | L17: #23 | M17: 2-2, 3-2 | N17: 수정(v9): 새 폴더 위치를 정리 적용(F07-01)과 같이 북마크바로 맞춤
A18: 앱 폴더 | B18: 팀원 C | C18: 팀원 D | D18: F03 | E18: 앱 폴더 | F18: P2 | G18: F03-05 | H18: 정상 | I18: Event-driven | J18: WHEN 사용자가 앱 폴더의 이름을 바꾸면 THE 시스템은 SHALL 크롬 북마크 폴더의 이름을 바꾸고, 크롬 북마크 관리자에도 같은 이름이 보인다. | K18: 새 탭 메인 | L18: #23 | M18: 2-2, 3-2
A19: 앱 폴더 | B19: 팀원 C | C19: 팀원 D | D19: F03 | E19: 앱 폴더 | F19: P2 | G19: F03-06 | H19: 정상 | I19: Event-driven | J19: WHEN 사용자가 앱 폴더를 삭제하면 THE 시스템은 SHALL 안의 북마크를 그 폴더의 상위 폴더로 꺼낸 뒤 폴더만 삭제한다. | K19: 새 탭 메인 | L19: #23 | M19: 2-2, 3-2 | N19: 제안: 꺼내는 위치는 상위 폴더
A20: 앱 폴더 | B20: 팀원 C | C20: 팀원 D | D20: F03 | E20: 앱 폴더 | F20: P2 | G20: F03-07 | H20: 예외 | I20: Unwanted | J20: IF 입력한 폴더 이름이 비어 있거나 공백뿐이면 THEN THE 시스템은 SHALL 폴더를 만들거나 바꾸지 않고 "폴더 이름을 입력해 주세요"를 표시한다. | K20: 새 탭 메인 | L20: #23 | M20: 2-2, 3-2 | N20: 제안
A21: 앱 폴더 | B21: 팀원 C | C21: 팀원 D | D21: F03 | E21: 앱 폴더 | F21: P2 | G21: F03-08 | H21: 예외 | I21: Unwanted | J21: IF 앱 폴더 안에 하위 폴더가 있으면 THEN THE 팝업은 SHALL 하위 폴더를 앱 폴더로 표시하고, 누르면 같은 팝업 안에서 그 폴더로 들어간다. | K21: 새 탭 메인 | L21: #23 | M21: 2-2, 3-2 | N21: 확정(v5) · 실행 확인: 팝업 위쪽에 상위 폴더로 돌아가는 버튼을 둠
A22: 재발견 | B22: 팀원 B | D22: F04 | E22: 잊고 있던 북마크 (재발견) | F22: P1 | G22: F04-01 | H22: 정상 | I22: Ubiquitous | J22: THE 시스템은 SHALL 마지막으로 연 지 30일 이상 지난 북마크를 위치(북마크바, 기타 북마크, 폴더 안)와 관계없이 "잊고 있던 북마크" 후보로 고른다. | K22: 화면 없음 | L22: #22 | M22: 2-3, 3-3
A23: 재발견 | B23: 팀원 B | D23: F04 | E23: 잊고 있던 북마크 (재발견) | F23: P1 | G23: F04-02 | H23: 정상 | I23: Ubiquitous | J23: THE 시스템은 SHALL 저장한 지 7일이 안 된 북마크, 독에 고정된 북마크, "이제 안 봐도 됨"을 누른 북마크, javascript:·chrome:// 주소의 북마크를 후보에서 뺀다. | K23: 화면 없음 | L23: #22 | M23: 2-3, 3-3 | N23: 참고: '7일이 안 된 북마크'는 30일 조건에 이미 포함돼 따로 구현할 필요 없음
A24: 재발견 | B24: 팀원 B | D24: F04 | E24: 잊고 있던 북마크 (재발견) | F24: P1 | G24: F04-03 | H24: 정상 | I24: Ubiquitous | J24: THE 시스템은 SHALL 마지막으로 연 시각을 lastOpenedByUs와 dateLastUsed 중 더 최근 값으로 정하고, 둘 다 없으면 dateAdded를 쓴다. | K24: 화면 없음 | L24: #22 | M24: 2-3, 3-3 | N24: 확정(v5): 둘 중 더 최근 값을 쓴다. 주소창으로만 여는 북마크가 후보에 나오는 한계는 받아들인다([이제 안 봐도 됨]으로 뺄 수 있음). 실행 확인(v3·v4): dateLastUsed는 북마크바 클릭과 북마크 관리자에서 열 때는 바뀌고, 주소창 입력·링크·우리 새 탭·tabs API로 열 때는 바뀌지 않음. 그래서 lastOpenedByUs 기록이 반드시 필요하고, 주소창으로만 여는 북마크는 '안 연 것'으로 보임(알려진 한계)
A25: 재발견 | B25: 팀원 B | C25: 팀원 D | D25: F04 | E25: 잊고 있던 북마크 (재발견) | F25: P1 | G25: F04-04 | H25: 정상 | I25: State-driven | J25: WHILE 후보가 1개 이상인 동안 THE 새 탭 화면은 SHALL 앱 폴더 줄 맨 앞에 "잊고 있던 북마크" 폴더를 표시하는 개수(최대 8) 배지와 함께 표시한다. | K25: 새 탭 메인 | L25: #22 | M25: 2-3, 3-3 | N25: 수정(v9): 확정 시안은 다른 폴더와 구별되는 어두운 색 카드
A26: 재발견 | B26: 팀원 B | C26: 팀원 D | D26: F04 | E26: 잊고 있던 북마크 (재발견) | F26: P1 | G26: F04-05 | H26: 정상 | I26: Event-driven | J26: WHEN 사용자가 "잊고 있던 북마크" 폴더를 클릭하면 THE 새 탭 화면은 SHALL 후보를 오래 안 연 순서로 최대 8개까지 팝업에 표시하고, 각 앱에 "N개월 전 저장"과 "N개월 전에 열어 봄"을 표시한다. | K26: 새 탭 메인 | L26: #22 | M26: 2-3, 3-3 | N26: 추가(v9): 설치 첫날에는 주소창으로 여는 북마크까지 대부분 후보가 되므로 8개 상한을 둠. 후보가 8개를 넘으면 "N개 더 있어요 · 모두 보기"로 나머지를 봄(P2). 열거나 고정하거나 [이제 안 봐도 됨]을 누르면 다음 후보가 올라옴
A27: 재발견 | B27: 팀원 B | D27: F04 | E27: 잊고 있던 북마크 (재발견) | F27: P1 | G27: F04-06 | H27: 정상 | I27: Ubiquitous | J27: THE 시스템은 SHALL "잊고 있던 북마크" 폴더를 크롬 북마크에 만들지 않고, 후보 북마크의 위치를 바꾸지 않는다. | K27: 화면 없음 | L27: #22 | M27: 2-3, 3-3
A28: 재발견 | B28: 팀원 B | C28: 팀원 D | D28: F04 | E28: 잊고 있던 북마크 (재발견) | F28: P1 | G28: F04-07 | H28: 정상 | I28: Event-driven | J28: WHEN 사용자가 후보 앱을 열면 THE 시스템은 SHALL 페이지를 열고 연 시각을 기록하며, 그 북마크를 후보에서 뺀다. | K28: 새 탭 메인 | L28: #22 | M28: 2-3, 3-3 | N28: 수정(v9): 아이콘과 제목 어느 쪽을 눌러도 열림
A29: 재발견 | B29: 팀원 B | C29: 팀원 D | D29: F04 | E29: 잊고 있던 북마크 (재발견) | F29: P2 | G29: F04-08 | H29: 정상 | I29: Event-driven | J29: WHEN 사용자가 후보 앱에서 [고정하기]를 누르면 THE 시스템은 SHALL 그 북마크를 독에 추가하고 후보에서 뺀다. | K29: 새 탭 메인 | L29: #23 | M29: 2-3, 3-3
A30: 재발견 | B30: 팀원 B | C30: 팀원 D | D30: F04 | E30: 잊고 있던 북마크 (재발견) | F30: P1 | G30: F04-09 | H30: 정상 | I30: Event-driven | J30: WHEN 사용자가 후보 앱에서 [이제 안 봐도 됨]을 누르면 THE 시스템은 SHALL 그 북마크를 dismissed에 기록해 다시 후보로 고르지 않고, [되돌리기] 버튼을 표시한다. | K30: 새 탭 메인 | L30: #22 | M30: 2-3, 3-3 | N30: 확정(v9): [되돌리기] 안내는 6초 동안 표시
A31: 재발견 | B31: 팀원 B | C31: 팀원 D | D31: F04 | E31: 잊고 있던 북마크 (재발견) | F31: P1 | G31: F04-10 | H31: 정상 | I31: Event-driven | J31: WHEN 사용자가 후보 앱에서 [어디 있는지 보기]를 누르면 THE 새 탭 화면은 SHALL 그 북마크가 들어 있는 앱 폴더의 팝업을 연다. | K31: 새 탭 메인 | L31: #22 | M31: 2-3, 3-3
A32: 재발견 | B32: 팀원 B | C32: 팀원 D | D32: F04 | E32: 잊고 있던 북마크 (재발견) | F32: P1 | G32: F04-11 | H32: 예외 | I32: Unwanted | J32: IF 후보가 하나도 없으면 THEN THE 새 탭 화면은 SHALL "잊고 있던 북마크" 폴더를 표시하지 않는다. | K32: 새 탭 메인 | L32: #22 | M32: 2-3, 3-3
A33: 재발견 | B33: 팀원 B | C33: 팀원 D | D33: F04 | E33: 잊고 있던 북마크 (재발견) | F33: P1 | G33: F04-12 | H33: 예외 | I33: Unwanted | J33: IF 북마크에 lastOpenedByUs와 dateLastUsed가 모두 없으면 THEN THE 새 탭 화면은 SHALL 그 앱에 "연 기록 없음"을 표시한다. | K33: 새 탭 메인 | L33: #22 | M33: 2-3, 3-3 | N33: 수정(v9): 주소창으로 여는 북마크는 기록이 남지 않아 "안 열어 봄"이 틀린 말이 됨
A34: 분류 규칙 | B34: 팀원 B | D34: F05 | E34: 분류와 폴더 계획 | F34: P1 | G34: F05-01 | H34: 정상 | I34: Ubiquitous | J34: THE 시스템은 SHALL 북마크를 ① 사이트 분류표 ② 주소 끝 규칙 ③ 제목 키워드 순서로 확인해, 처음 맞는 단계에서 카테고리 하나를 정하고 멈춘다. 사이트 분류표에서 여러 항목이 맞으면 더 긴(구체적인) 주소를 따른다. 주소가 categories.json의 '분류하지 않는 사이트'에 맞으면 주소 끝 규칙과 제목 키워드를 확인하지 않고 분류 안 됨으로 정한다. | K34: 화면 없음 | L34: #22 | M34: 2-5 ~ 2-8 | N34: 추가(v4) · 실행 확인: 앞의 www.는 떼고, 하위 주소(m.blog.naver.com)도 같은 항목으로 봄. blog.naver.com과 cafe.naver.com이 서로 다른 카테고리로 나뉘는 것을 확인 추가(v11): 분류하지 않는 사이트(뉴스·위키·검색 결과)는 제목 키워드 오분류를 막기 위한 것. 분류표 항목과 함께 비교하고 더 긴 주소를 따름. 주소 끝 규칙에 .edu 추가. 제목 키워드는 띄어쓰기를 없애지 않고 비교. 정의와 분류표 내용은 category-definitions.md
A35: 분류 규칙 | B35: 팀원 B | D35: F05 | E35: 분류와 폴더 계획 | F35: P1 | G35: F05-02 | H35: 정상 | I35: Ubiquitous | J35: THE 시스템은 SHALL 분류 결과마다 근거(맞은 단계와 맞은 규칙)를 함께 돌려준다. | K35: 화면 없음 | L35: #22 | M35: 2-5 ~ 2-8
A36: 분류 규칙 | B36: 팀원 B | D36: F05 | E36: 분류와 폴더 계획 | F36: P1 | G36: F05-03 | H36: 정상 | I36: Ubiquitous | J36: THE 시스템은 SHALL 분류표와 제목 키워드를 코드가 아닌 data/categories.json에서 읽는다. | K36: 화면 없음 | L36: #22 | M36: 2-5 ~ 2-8
A37: 폴더 계획 | B37: 팀원 C | D37: F05 | E37: 분류와 폴더 계획 | F37: P1 | G37: F05-04 | H37: 정상 | I37: Ubiquitous | J37: THE 시스템은 SHALL 북마크바·기타 북마크·모바일 북마크 바로 아래에 폴더 없이 흩어져 있는 북마크를 정리 대상으로 삼고, 사용자가 만든 폴더·최근 30일 안에 북마크바에서 연 북마크(dateLastUsed 기준)·javascript:와 chrome:// 주소·직접 옮긴 북마크는 뺀다. 단, 크롬의 가져오기 폴더(북마크바·기타 북마크·모바일 북마크 바로 아래에 있고 이름이 목록에 있는 폴더)는 사용자가 만든 폴더로 보지 않고, 그 바로 아래의 북마크를 정리 대상에 넣는다. | K37: 화면 없음 | L37: #22 | M37: 2-5 ~ 2-8 | N37: 수정(v9): 북마크바를 기본 정리 대상에 포함(크롬 별 버튼의 기본 저장 위치가 북마크바). 요즘 쓰는 북마크는 폴더에 넣지 않고 카테고리 개수에도 세지 않음 / 확정(v5): 기타 북마크가 계정용·이 PC 전용 두 개면 한쪽(동기화되는 쪽)만 정리 대상으로 삼음. 이 PC 전용 북마크를 계정 쪽으로 옮기면 사용자 모르게 계정에 올라가기 때문 확정(v12, 10월 7일): 크롬 가져오기 폴더는 사용자 폴더로 보지 않는다. 실행 확인: 북마크가 없는 새 프로필에 HTML을 가져오면 북마크바 항목은 북마크바에 그대로, 나머지는 기타 북마크가 아니라 북마크바 맨 끝의 "가져온 북마크" 폴더에 들어감. 다른 브라우저에서 옮겨 온 사용자도 같은 폴더를 가짐. 크롬이 가져오기 폴더에 따로 표시를 남기지 않아 폴더 이름으로 판단함. 이름 목록: "가져온 북마크"(한국어 크롬에서 HTML 가져오기로 확인, 10월 7일). 확인 필요: 영어 크롬의 "Imported", 다른 브라우저에서 가져온 경우의 "Imported From …"·"…에서 가져옴", 같은 이름이 이미 있을 때 뒤에 붙는 " (1)" 같은 번호. 가져오기 폴더 안의 폴더는 사용자 폴더로 봄. 사용자가 같은 이름의 폴더를 직접 만들었으면 그 폴더도 대상이 되는 한계가 있음(첫 정리 카드에서 미리 보여 주고 되돌릴 수 있음). 화면에서는 가져오기 폴더도 보통 앱 폴더로 표시(F03-01)
A38: 폴더 계획 | B38: 팀원 C | D38: F05 | E38: 분류와 폴더 계획 | F38: P1 | G38: F05-05 | H38: 정상 | I38: Ubiquitous | J38: THE 시스템은 SHALL 정리 대상이 10~29개면 최대 3개, 30~59개면 최대 4개, 60~99개면 최대 5개, 100개 이상이면 최대 6개의 폴더를 북마크가 많은 카테고리부터 계획한다. | K38: 화면 없음 | L38: #22 | M38: 2-5 ~ 2-8
A39: 폴더 계획 | B39: 팀원 C | D39: F05 | E39: 분류와 폴더 계획 | F39: P1 | G39: F05-06 | H39: 정상 | I39: Ubiquitous | J39: THE 시스템은 SHALL 북마크가 3개 미만인 카테고리를 폴더로 계획하지 않고, "기타" 폴더를 만들지 않는다. | K39: 화면 없음 | L39: #22 | M39: 2-5 ~ 2-8
A40: 폴더 계획 | B40: 팀원 C | D40: F05 | E40: 분류와 폴더 계획 | F40: P1 | G40: F05-07 | H40: 정상 | I40: Ubiquitous | J40: THE 시스템은 SHALL 같은 북마크 목록과 같은 분류표에 대해 항상 같은 계획을 돌려주고, 개수가 같은 카테고리는 categories.json에 적힌 순서로 고른다. | K40: 화면 없음 | L40: #22 | M40: 2-5 ~ 2-8 | N40: 제안: 동점 처리 기준
...

Sheet API_크롬
A1: 도메인 | B1: 담당(안) | C1: ID | D1: 분류 | E1: 메서드 · 이벤트 | F1: 필요 권한 | G1: 입력 | H1: 출력 · 이벤트 값 | I1: 용도 | J1: 호출 위치 | K1: 주의 · 예외 | L1: 관련 기능
A2: 확장 프로그램 설정 | B2: 팀원 A | C2: C01 | D2: manifest | E2: chrome_url_overrides.newtab | F2: 없음 (설치 시 '새 탭 페이지 변경' 안내) | G2: "newtab.html" | H2: — | I2: 새 탭을 확장 프로그램 화면으로 바꿈 | J2: manifest.json | K2: 주소창 포커스는 크롬이 그대로 유지. 확장 프로그램 화면은 HTML 안에 직접 쓴 스크립트(<script>코드</script>, onclick 속성)를 실행하지 못하므로 모든 코드는 .js 파일에 두고 addEventListener로 연결. eval과 new Function도 막힘(실행 확인) | L2: F11, F12
A3: 확장 프로그램 설정 | B3: 팀원 A | C3: C02 | D3: manifest | E3: background.service_worker | F3: 없음 | G3: "background.js", type: "module" | H3: — | I3: 새 탭이 닫혀 있어도 북마크 알림을 받음 | J3: manifest.json | K3: 30초쯤 쉬면 꺼졌다가 알림이 오면 다시 켜짐. 변수에 상태를 두지 말고 저장소에 기록. 알림 리스너는 파일 맨 위에서 바로 등록(나중에 등록하면 깨어날 때 알림을 놓침) | L3: F01, F07, F10
A4: 확장 프로그램 설정 | B4: 팀원 B | C4: C03 | D4: runtime | E4: onInstalled | F4: 없음 | G4: — | H4: { reason } | I4: 서비스 워커가 쓰는 저장 항목(manualMoves, newBookmarks)의 빈 기본값을 처음 한 번 만듦 | J4: background.js | K4: reason이 "install"일 때만 기록 (업데이트 때 덮어쓰지 않음). 새 탭이 쓰는 state는 건드리지 않음 | L4: F07, F10
A5: 북마크 동기화 | B5: 팀원 A | C5: C04 | D5: bookmarks | E5: getTree() | F5: bookmarks | G5: 없음 | H5: BookmarkTreeNode[] (최상위 1개, 그 아래 북마크바·기타·모바일) | I5: 북마크 전체 읽기 | J5: bookmarks.js | K5: 노드 필드: id, parentId, index, title, url, dateAdded, dateLastUsed, folderType, syncing, children. 실행 확인(v3): 로그인하지 않은 크롬에는 모바일 북마크 폴더가 아예 없고, 한 번도 안 연 북마크에는 dateLastUsed 필드가 없음 | L5: F01 ~ F05, F14
A6: 앱 폴더 | B6: 팀원 A | C6: C05 | D6: bookmarks | E6: create({parentId, index?, title, url?}) | F6: bookmarks | G6: url이 없으면 폴더 생성 | H6: 만들어진 노드 | I6: 정리 폴더·앱 폴더 만들기 | J6: bookmarks.js | K6: folderType이 있는 최상위 폴더 바로 아래에는 만들 수 있음. 최상위(루트) 자체에는 못 만듦 | L6: F03, F07, F16
A7: 정리 적용 | B7: 팀원 A | C7: C06 | D7: bookmarks | E7: move(id, {parentId?, index?}) | F7: bookmarks | G7: 옮길 북마크 ID, 목적지 폴더, 순서 | H7: 옮겨진 노드 | I7: 정리 적용, 우클릭·드래그 이동, 되돌리기 | J7: bookmarks.js, organize.js | K7: 하나를 옮기면 같은 폴더의 뒤쪽 index가 바뀜. 되돌릴 때는 원래 index가 작은 것부터. 없는 ID면 오류. index가 목적지 폴더의 개수보다 크면 "Index out of bounds" 오류이므로 개수에 맞춰 줄임(실행 확인). 같은 폴더 안에서 뒤쪽으로 옮기면 한 칸 앞에 놓임(실행 확인) | L7: F07, F10, F13, F15, F17
A8: 앱 폴더 | B8: 팀원 A | C8: C07 | D8: bookmarks | E8: update(id, {title?, url?}) | F8: bookmarks | G8: 폴더 ID, 새 이름 | H8: 바뀐 노드 | I8: 앱 폴더 이름 바꾸기 | J8: bookmarks.js | K8: folderType이 있는 폴더는 바꿀 수 없음(오류) | L8: F03
A9: 앱 폴더 | B9: 팀원 A | C9: C08 | D9: bookmarks | E9: remove(id) | F9: bookmarks | G9: 폴더 ID | H9: 없음 | I9: 빈 폴더 삭제 | J9: bookmarks.js | K9: 비어 있지 않은 폴더는 오류(실행 확인). 안의 북마크를 먼저 꺼낸 뒤 호출. removeTree()는 쓰지 않음(북마크까지 지워짐) | L9: F03, F13
A10: 새 북마크 정리 | B10: 팀원 B | C10: C09 | D10: bookmarks | E10: onCreated | F10: bookmarks | G10: — | H10: (id, node) | I10: 새 북마크 기록, 화면 반영 | J10: background.js, render.js | K10: 가져오기 중에는 대량으로 발생 | L10: F01, F10
A11: 직접 옮김 감지 | B11: 팀원 B | C11: C10 | D11: bookmarks | E11: onMoved | F11: bookmarks | G11: — | H11: (id, {parentId, index, oldParentId, oldIndex}) | I11: 직접 옮김 기록, 화면 반영 | J11: background.js, render.js | K11: pendingMoves에 같은 ID·같은 목적지가 1분 안에 기록돼 있으면 직접 옮김으로 기록하지 않음. parentId와 oldParentId가 같으면(순서만 바뀜) 기록하지 않음 | L11: F01, F07
A12: 북마크 동기화 | B12: 팀원 D | C12: C11 | D12: bookmarks | E12: onChanged | F12: bookmarks | G12: — | H12: (id, {title, url?}) | I12: 제목·주소 변경을 화면에 반영 | J12: render.js | L12: F01
A13: 북마크 동기화 | B13: 팀원 B | C13: C12 | D13: bookmarks | E13: onRemoved | F13: bookmarks | G13: — | H13: (id, {parentId, index, node}) | I13: 화면 반영, 저장 항목에서 ID 정리 | J13: background.js, render.js | K13: 폴더가 통째로 지워지면 알림은 폴더 것 하나만 오고 안의 북마크는 node.children에 들어 있음(실행 확인). 그 ID도 함께 정리 | L13: F01, F08
A14: 북마크 동기화 | B14: 팀원 B | C14: C13 | D14: bookmarks | E14: onImportBegan / onImportEnded | F14: bookmarks | G14: — | H14: 없음 | I14: 가져오기 중 onCreated 처리 멈춤 | J14: background.js | K14: 끝난 뒤 getTree()로 한 번만 다시 읽음 | L14: F01
A15: 저장 항목 | B15: 팀원 A | C15: C14 | D15: storage | E15: local.get(keys) | F15: storage | G15: 키 이름 또는 배열 | H15: {키: 값} | I15: 저장 항목 읽기 | J15: store.js | K15: 값이 없으면 키가 빠진 채로 옴. 기본값을 store.js에서 채움 | L15: F04, F07 ~ F10, F13
A16: 저장 항목 | B16: 팀원 A | C16: C15 | D16: storage | E16: local.set({키: 값}) | F16: storage | G16: 저장할 값 | H16: 없음 | I16: 저장 항목 쓰기 | J16: store.js | K16: 새 탭과 서비스 워커가 같은 키를 동시에 쓰면 한쪽 값이 사라짐. 그래서 한 키는 한쪽만 쓴다(참고_저장 항목 시트). 같은 쪽 안에서는 읽고 → 고치고 → 쓰기를 store.js의 한 함수로 묶어 순서대로 처리 | L16: F04, F07 ~ F10, F13
A17: 저장 항목 | B17: 팀원 D | C17: C16 | D17: storage | E17: onChanged | F17: storage | G17: — | H17: (changes, areaName) | I17: 서비스 워커가 쓴 값을 새 탭이 알아채 화면 갱신 | J17: render.js | K17: areaName이 "local"일 때만 처리 | L17: F01, F10
A18: 웹 검색 | B18: 팀원 D | C18: C17 | D18: search | E18: query({text, disposition}) | F18: search | G18: 검색어, "CURRENT_TAB" | H18: 없음 | I18: 크롬 기본 검색엔진으로 검색 | J18: search.js | K18: text가 빈 문자열이면 "Empty text parameter" 오류(실행 확인)이므로 호출하지 않음 | L18: F11
A19: 앱 표시·열기 | B19: 팀원 A | C19: C18 | D19: tabs | E19: update({url}) / create({url}) | F19: 없음 | G19: 열 주소 | H19: Tab | I19: 주소 입력 이동, chrome://·file:// 북마크 열기, 새 탭에서 열기 | J19: bookmarks.js, search.js | K19: 주소만 넘기는 용도는 tabs 권한이 필요 없음 | L19: F02, F11, F15
A20: 고정 제안 | B20: 팀원 D | C20: C19 | D20: permissions | E20: request({permissions: ["topSites"]}) | F20: 선택 권한: topSites | G20: — | H20: 허락 여부(true/false) | I20: [고정하기]를 누를 때 권한 요청 | J20: view/cards.js | K20: view/cards.js가 요청하고 결과(목록)만 plan.js의 pickPinCandidates에 넘긴다. plan.js는 크롬 API를 부르지 않는다. 반드시 클릭 핸들러 안에서 바로 호출(그 전에 await가 있으면 실패). 거절하면 false. 허락 전에는 chrome.topSites 자체가 없음(실행 확인). 허락하면 true, 거절하면 false(실행 확인 v4). 허락 직후 새로고침 없이 chrome.topSites를 쓸 수 있음 | L20: F09
A21: 고정 제안 | B21: 팀원 D | C21: C20 | D21: permissions | E21: contains({permissions: ["topSites"]}) | F21: 없음 | G21: — | H21: true/false | I21: 이미 허락했는지 확인 | J21: view/cards.js | L21: F09
A22: 고정 제안 | B22: 팀원 D | C22: C21 | D22: topSites | E22: get() | F22: 선택 권한: topSites | G22: 없음 | H22: [{url, title}, …] (최대 10개쯤) | I22: 자주 방문한 사이트 목록 읽기 (비교는 plan.js가 계산) | J22: view/cards.js | K22: 방문 기록을 지웠으면 빈 배열. 결과를 저장하지 않음. 실행 확인(v4): 목록에 확장 프로그램 자신의 새 탭 주소(chrome-extension://…)가 들어 있으므로 http·https 주소만 사용 | L22: F09
A23: 앱 표시·열기 | B23: 팀원 A | C23: C22 | D23: favicon | E23: runtime.getURL("/_favicon/") + ?pageUrl=…&size=32 | F23: favicon | G23: 북마크 주소, 크기 | H23: 이미지 주소 | I23: 사이트 아이콘 표시 | J23: bookmarks.js | K23: 파비콘이 없으면 오류가 아니라 기본 그림이 오고, 그 그림은 어느 주소든 똑같음(실행 확인). 사이트가 아닌 페이지 주소 단위로 찾음. 대부분 16~32px | L23: F02, F14

Sheet API_내부 함수
A1: 도메인 | B1: 담당(안) | C1: ID | D1: 파일 | E1: 함수 | F1: 입력 | G1: 출력 | H1: 동작 | I1: 크롬 북마크 변경 | J1: 저장소 쓰기 | K1: 예외 처리 · 주의 | L1: 관련 기능 | M1: 관련 이슈
A2: 북마크 동기화 | B2: 팀원 A | C2: N01 | D2: bookmarks.js | E2: loadTree() | F2: 없음 | G2: { roots: {bar, other, mobile}, bookmarks: [...], folders: [...] } | H2: 크롬 북마크를 읽어 화면과 규칙이 쓰기 쉬운 목록으로 바꿈. 각 북마크에 들어 있는 폴더와 최상위 폴더 종류를 붙임 | I2: 없음 | J2: 없음 | K2: 기타 북마크가 두 개면 syncing이 true인 쪽을 roots.other로 돌려줌. 북마크바가 두 개로 보이는 경우도 같은 방식으로 roots.bar를 정함(v9, 개발 첫 주에 확인). 모바일 북마크 폴더가 없으면 roots.mobile은 null | L2: F01 | M2: #2
A3: 앱 폴더 | B3: 팀원 A | C3: N02 | D3: bookmarks.js | E3: createFolder(name, parentId) | F3: 폴더 이름, 상위 폴더 ID | G3: 폴더 노드 | H3: 같은 이름의 폴더가 상위 폴더 안에 있으면 그 폴더를, 없으면 새로 만들어 돌려줌 | I3: 폴더 생성 | J3: 없음 | K3: 이름이 비어 있으면 오류를 던짐 | L3: F03, F07 | M3: #2
A4: 정리 적용 | B4: 팀원 A | C4: N03 | D4: bookmarks.js | E4: moveBookmark(id, parentId, index?) | F4: 북마크 ID, 목적지 폴더, 순서 | G4: 옮겨진 노드 또는 null | H4: 북마크 하나를 옮김 | I4: 이동 | J4: 없음 | K4: 북마크가 없으면 null을 돌려줌(오류를 던지지 않음) | L4: F07, F13, F15 | M4: #2
A5: 앱 폴더 | B5: 팀원 A | C5: N04 | D5: bookmarks.js | E5: renameFolder(id, name) | F5: 폴더 ID, 새 이름 | G5: 바뀐 노드 | H5: 앱 폴더 이름 바꾸기 | I5: 이름 변경 | J5: 없음 | K5: folderType이 있는 폴더, 빈 이름이면 오류 | L5: F03 | M5: #2
A6: 앱 폴더 | B6: 팀원 A | C6: N05 | D6: bookmarks.js | E6: deleteFolderKeepChildren(id) | F6: 폴더 ID | G6: 꺼낸 북마크 수 | H6: 안의 북마크를 상위 폴더로 꺼낸 뒤 폴더만 삭제 | I6: 이동, 폴더 삭제 | J6: pendingMoves | K6: 꺼내는 이동이 직접 옮김으로 기록되지 않게 pendingMoves에 먼저 저장 | L6: F03 | M6: #2
A7: 앱 표시·열기 | B7: 팀원 A | C7: N06 | D7: bookmarks.js | E7: openBookmark(bookmark, {newTab}) | F7: 북마크, 새 탭 여부 | G7: 없음 (javascript: 주소여서 열지 않았으면 false) | H7: 연 시각을 기록한 뒤 주소를 엶. chrome://·file://은 tabs API로 엶 | I7: 없음 | J7: lastOpenedByUs | K7: javascript: 주소면 열지 않고 false. Ctrl+클릭·가운데 클릭은 새 탭으로. 현재 탭 이동은 tabs 권한 없이 됨(실행 확인) | L7: F02, F04, F14, F15 | M7: #2
A8: 앱 표시·열기 | B8: 팀원 A | C8: N07 | D8: bookmarks.js | E8: faviconUrl(url, size) / hasFavicon(url) | F8: 주소, 크기 / 주소 | G8: 이미지 주소 / true·false | H8: _favicon 주소 만들기 / 받은 그림이 기본 그림과 같은지 비교 | I8: 없음 | J8: 없음 | K8: 기본 그림은 방문한 적 없는 주소(예: https://no-favicon.invalid/)로 한 번 받아 두고 비교. 없으면 사이트 첫 페이지 주소로 한 번 더 확인 | L8: F02 | M8: #2
A9: 저장 항목 | B9: 팀원 A | C9: N08 | D9: store.js | E9: load() | F9: 없음 | G9: 저장 항목 전체 (없는 키는 기본값) | H9: 저장 항목을 한 번에 읽음 | I9: 없음 | J9: 없음 | L9: 전체 | M9: #3
A10: 저장 항목 | B10: 팀원 A | C10: N09 | D10: store.js | E10: update(key, fn) | F10: 키, 값을 고치는 함수 | G10: 고친 값 | H10: 읽고 → 고치고 → 쓰기를 한 번에 처리 | I10: 없음 | J10: 해당 키 | K10: 같은 키를 동시에 고치지 않도록 순서대로 처리 | L10: 전체 | M10: #3
A11: 재발견 | B11: 팀원 A | C11: N10 | D11: store.js | E11: recordOpened(id) | F11: 북마크 ID | G11: 없음 | H11: 연 시각 기록 | I11: 없음 | J11: lastOpenedByUs | L11: F02, F04 | M11: #3
A12: 고정(독) | B12: 팀원 A | C12: N11 | D12: store.js | E12: pin(id) / unpin(id) | F12: 북마크 ID | G12: true·false / 고정 목록 | H12: 독에 추가·제거 | I12: 없음 | J12: pinned | K12: 이미 있으면 다시 넣지 않음. 이미 8개면 넣지 않고 false | L12: F08, F09 | M12: #3
A13: 재발견 | B13: 팀원 A | C13: N12 | D13: store.js | E13: dismiss(id) / undismiss(id) | F13: 북마크 ID | G13: 없음 | H13: "이제 안 봐도 됨" 기록·취소 | I13: 없음 | J13: dismissed | L13: F04 | M13: #3
A14: 직접 옮김 감지 | B14: 팀원 A | C14: N13 | D14: store.js | E14: markManualMove(id) | F14: 북마크 ID | G14: 없음 | H14: 직접 옮김 기록 | I14: 없음 | J14: manualMoves | K14: 서비스 워커만 호출 (새 탭은 호출하지 않음) | L14: F07, F15, F17 | M14: #3
A15: 직접 옮김 감지 | B15: 팀원 A | C15: N14 | D15: store.js | E15: setPending(moves) / isPending(id, parentId) | F15: [{북마크ID, 목적지 폴더}] / 북마크 ID, 옮겨진 폴더 | G15: 없음 / true·false | H15: 우리 정리가 옮길 북마크를 목적지·시각과 함께 표시 / 그 이동이 우리 것인지 확인 | I15: 없음 | J15: pendingMoves (setPending만) | K15: setPending은 새 탭만, isPending은 서비스 워커만 호출. 표시는 지우지 않고 1분 뒤 만료. setPending 때 만료된 항목을 함께 지움. 반드시 저장이 끝난 뒤(await) 옮기기 시작 | L15: F07, F13 | M15: #3
A16: 되돌리기·정리 기록 | B16: 팀원 A | C16: N15 | D16: store.js | E16: addHistory(entry) / markUndone(historyId) | F16: 정리 기록 한 건 / 기록 ID | G16: 없음 | H16: 정리 기록 추가, 되돌린 시각 기록 | I16: 없음 | J16: history | L16: F07, F13 | M16: #3
A17: 저장 항목 | B17: 팀원 A | C17: N16 | D17: store.js | E17: cleanupMissing(tree) | F17: 북마크 목록 | G17: 지운 개수 | H17: 새 탭이 열릴 때, 크롬에 더 이상 없는 북마크 ID를 새 탭이 쓰는 저장 항목에서 지움 | I17: 없음 | J17: pinned, lastOpenedByUs, dismissed, handledNew | K17: history는 지우지 않음(기록 화면에서 제목을 보여 주기 위해). 서비스 워커가 쓰는 키는 건드리지 않음 | L17: F01 | M17: #3
A18: 분류 규칙 | B18: 팀원 B | C18: N17 | D18: classify.js | E18: classify(bookmark, categories) | F18: 북마크 {title, url}, 분류표 { categories: [{ name, sites, suffixes, keywords }], noCategorySites: [] } | G18: { category, step: "site" | "suffix" | "keyword", rule, needsCheck } 또는 { category: null } | H18: 분류표 → 주소 끝 → 제목 키워드 순서로 확인해 처음 맞는 곳에서 멈춤 | I18: 없음 | J18: 없음 | K18: 주소를 해석할 수 없으면 { category: null }. 크롬 API를 쓰지 않는 순수 함수 v11: 주소가 noCategorySites(분류하지 않는 사이트)에 맞으면 주소 끝·제목 키워드를 보지 않고 { category: null }. 분류표 항목과 함께 비교해 더 긴 주소를 따름. 호스트 비교는 점(.) 단위(같거나 '.'+항목으로 끝남). 제목 키워드는 띄어쓰기를 없애지 않고 비교 | L18: F05 | M18: #7
A19: 분류 규칙 | B19: 팀원 B | C19: N18 | D19: classify.js | E19: measure(samples, answers, categories) | F19: 샘플 북마크, 정답지, 분류표 | G19: { coverage, accuracy, wrong } (적용률, 정확도, 틀린 목록. v11에서 이름 확정) | H19: 정답지와 비교해 적용률·정확도 계산 | I19: 없음 | J19: 없음 | L19: F05 | M19: #7
A20: 폴더 계획 | B20: 팀원 C | C20: N19 | D20: plan.js | E20: getTargets(tree, stored, options, now) | F20: 북마크 목록, 저장 항목, {북마크바 제외, 포함할 사용자 폴더}, 현재 시각 | G20: 정리 대상 북마크 배열 | H20: 북마크바·기타·모바일과 크롬 가져오기 폴더의 바로 아래에 흩어진 북마크를 고르고 제외 대상(사용자 폴더, 최근 30일 안에 북마크바에서 연 북마크, 직접 옮긴 북마크 등)을 뺌 | I20: 없음 | J20: 없음 | K20: loadTree가 고른 북마크바·기타·모바일 북마크(roots)의 바로 아래만 대상(v9: 북마크바 포함). 요즘 쓰는 북마크는 dateLastUsed로 판단하고 now를 입력으로 받아 테스트 가능. 기타 북마크가 두 개일 때 다른 쪽은 건드리지 않음 v12: 크롬의 가져오기 폴더(roots 바로 아래에 있고 이름이 목록에 있는 폴더)는 사용자 폴더로 보지 않고, 그 바로 아래의 북마크도 대상에 넣음. 가져오기 폴더 안의 폴더는 사용자 폴더. 이름 목록은 plan.js 맨 위의 상수로 관리(언어마다 이름이 다름. 함수의 입력은 바꾸지 않음). 이름 목록: "가져온 북마크"(한국어 크롬에서 HTML 가져오기로 확인, 10월 7일). 확인 필요: 영어 크롬의 "Imported", 다른 브라우저에서 가져온 경우의 "Imported From …"·"…에서 가져옴", 같은 이름이 이미 있을 때 뒤에 붙는 " (1)" 같은 번호 | L20: F05 | M20: #11
A21: 폴더 계획 | B21: 팀원 C | C21: N20 | D21: plan.js | E21: makePlan(targets, categories) | F21: 정리 대상, 분류표 | G21: { type: "folders", folders: [{name, items, reasons}], rest } 또는 { type: "pin", reason } | H21: 개수에 맞는 폴더 수를 정하고, 많은 카테고리부터 폴더로 계획 | I21: 없음 | J21: 없음 | K21: 10개 미만이거나 3개 이상 모인 카테고리가 없으면 type: "pin" | L21: F05, F06, F09 | M21: #11
A22: 고정 제안 | B22: 팀원 C | C22: N21 | D22: plan.js | E22: pickPinCandidates(bookmarks, topSites, stored) | F22: 북마크, 자주 방문한 사이트(없으면 빈 배열), 저장 항목 | G22: 북마크 최대 5개 | H22: 자주 방문한 사이트와 호스트가 같은 북마크 먼저, 부족하면 최근에 연 순 | I22: 없음 | J22: 없음 | K22: topSites가 비어 있으면 최근에 연 순만. http·https가 아닌 항목은 건너뜀. 연 적 없는 북마크는 후보가 아니므로 결과가 0개일 수 있음(F09-09) | L22: F09 | M22: #11
A23: 정리 적용 | B23: 팀원 A | C23: N22 | D23: organize.js | E23: applyPlan(plan, type) | F23: 폴더 계획 { folders: [{ name 또는 folderId, items }], keep? }, "first" | "new" | G23: 정리 기록 한 건 { id, at, type, createdFolderIds, moves, fromOrder, skipped } | H23: 폴더를 만들고 북마크를 옮긴 뒤 기록을 저장 | I23: 폴더 생성, 이동 | J23: pendingMoves, history, handledNew | K23: 순서: ① 모든 북마크의 원래 폴더와, 원래 폴더별 전체 순서(fromOrder)를 읽어 둠 ② 북마크바(roots.bar) 맨 뒤에 폴더 생성 ③ setPending(저장 완료까지 기다림) ④ 이동 ⑤ history 저장. 옮기지 못한 북마크는 건너뛰고 skipped에 개수를 담음. '그대로 두기'로 둔 새 북마크는 handledNew에 기록 | L23: F07, F10 | M23: #4
A24: 되돌리기·정리 기록 | B24: 팀원 A | C24: N23 | D24: organize.js | E24: undo(historyId) | F24: 정리 기록 ID | G24: { restored, skipped, fallback } | H24: 원래 순서가 앞인 것부터, 원래 순서에서 바로 앞에 있던 이웃의 뒤에 끼워 넣어 되돌림 | I24: 이동, 빈 폴더 삭제 | J24: pendingMoves, history | K24: 지금 그 정리가 넣은 폴더에 없는 북마크(직접 옮김)·삭제된 북마크는 skipped, 원래 폴더가 없으면 기타 북마크로 옮기고 fallback. 앞 이웃이 하나도 없으면 맨 앞으로. 북마크별 실제 목적지(원래 폴더 또는 기타 북마크)를 먼저 정한 뒤 setPending | L24: F13 | M24: #4
A25: 새 북마크 정리 | B25: 팀원 B | C25: N24 | D25: classify.js | E25: suggestForNew(newBookmarks, folders, categories) | F25: 새 북마크, 현재 폴더, 분류표 | G25: [{ bookmarkId, folderId 또는 null }], 새 폴더 제안 | H25: 새 북마크마다 추천 폴더를 정함 | I25: 없음 | J25: 없음 | K25: 추천할 폴더가 없으면 folderId: null (그대로 두기) | L25: F10 | M25: #7
A26: 재발견 | B26: 팀원 B | C26: N25 | D26: forgotten.js | E26: lastOpened(bookmark, stored) | F26: 북마크, 저장 항목 | G26: { time, source: "us" | "chrome" | "added" } | H26: 마지막으로 연 시각과 그 출처 | I26: 없음 | J26: 없음 | K26: source가 "added"이면 화면에 "연 기록 없음" 표시 | L26: F04 | M26: #8
A27: 재발견 | B27: 팀원 B | C27: N26 | D27: forgotten.js | E27: pickForgotten(bookmarks, stored, now) | F27: 북마크, 저장 항목, 현재 시각 | G27: 북마크 배열 (오래 안 연 순) | H27: 30일 이상 안 연 북마크를 고르고 제외 대상을 뺌. 화면은 앞의 8개만 표시(v9) | I27: 없음 | J27: 없음 | K27: now를 입력으로 받아 날짜를 바꿔 가며 테스트 가능 | L27: F04 | M27: #8
A28: 북마크 검색 | B28: 팀원 D | C28: N27 | D28: search.js | E28: searchBookmarks(query, bookmarks) | F28: 입력 글자, 북마크 | G28: 일치하는 북마크 배열 | H28: 제목·주소 부분 일치(대소문자 무시) | I28: 없음 | J28: 없음 | K28: 빈 입력이면 빈 배열 | L28: F14 | M28: #18
A29: 웹 검색 | B29: 팀원 D | C29: N28 | D29: search.js | E29: isUrlLike(text) | F29: 입력 글자 | G29: true/false | H29: http(s)://로 시작하거나 띄어쓰기 없이 점이 있으면 true | I29: 없음 | J29: 없음 | L29: F11 | M29: #18
A30: 웹 검색 | B30: 팀원 D | C30: N29 | D30: search.js | E30: runWebSearch(text) | F30: 입력 글자 | G30: 없음 | H30: 주소면 이동, 아니면 기본 검색엔진으로 검색 | I30: 없음 | J30: 없음 | K30: 빈 입력이면 아무것도 하지 않음 | L30: F11 | M30: #18
A31: 화면 배치 | B31: 팀원 D | C31: N30 | D31: render.js | E31: renderAll(tree, stored) | F31: 북마크 목록, 저장 항목 | G31: 없음 | H31: 화면의 시작점. 헤더·날짜·화면 아래의 고정됨(독)·모든 북마크를 직접 그리고, 각 화면 파일(view/*)의 그리기 함수를 부름. 북마크 알림이나 저장소 변경이 오면 호출. 화면 파일끼리 서로 부르지 않도록, 다른 화면 파일의 동작이 필요한 그리기 함수에는 동작 묶음(actions)을 만들어 넘김(v13) | I31: 없음 | J31: 없음 | K31: 북마크가 없으면 안내 문구. 크롬 북마크 알림과 저장소 알림은 이 파일만 받음 (v10) v13: actions = { openFolder(folderId) → openFolderPopup, showResultNotice(entry) → showResultNotice, showContextMenu(bookmark) → showContextMenu }. 각 화면 파일은 자기 칸 안만 그림. 칸 이름은 file-structure.md 12번 | L31: F01 ~ F04, F08, F12 | M31: #15
A32: 정리 카드 | B32: 팀원 D | C32: N31 | D32: view/cards.js | E32: showFirstCard(plan, actions) / showOrganizeDialog(plan, actions) / showPinPicker() | F32: 폴더 계획, 동작 묶음 { showResultNotice } / 폴더 계획, 동작 묶음 / 없음 | G32: 없음 | H32: 첫 정리 카드(또는 고정 제안 카드), 자세히 보기와 [정리하기] 창, 고정할 북마크 고르기 창 표시. 고정 제안의 [고정하기]에서 권한을 요청하고 자주 방문한 사이트 목록을 받아 plan.js에 넘김 | I32: 없음 | J32: state.firstCard | K32: Esc·바깥 클릭으로 닫힘. 화면 파일끼리는 서로 부르지 않고 render.js가 부름 (v10: render.js에서 분리) v13: 첫 정리 카드는 #organize-suggestion 칸에 그림. [정리하기]로 applyPlan이 끝나면 actions.showResultNotice(entry)를 부름. showOrganizeDialog가 폴더 계획을 입력으로 받게 함(cards.js는 plan.js를 부르지 않음). 새 북마크 정리(F10)와 고르기 창(F09)에 필요한 입력은 P2를 시작할 때 정함 | L32: F06, F09, F10 | M32: #17
A33: 새 북마크 정리 | B33: 팀원 B | C33: N32 | D33: background.js | E33: onCreated 처리 | F33: (id, node) | G33: 없음 | H33: 북마크바·기타·모바일 바로 아래에 저장된 새 북마크를 newBookmarks에 추가 | I33: 없음 | J33: newBookmarks | K33: 가져오기 중이거나, 폴더이거나, 사용자 폴더 안에 저장된 것이면 추가하지 않음 | L33: F10 | M33: #6
A34: 직접 옮김 감지 | B34: 팀원 B | C34: N33 | D34: background.js | E34: onMoved 처리 | F34: (id, moveInfo) | G34: 없음 | H34: 폴더가 바뀐 이동이면 newBookmarks에서 지우고, 우리 정리의 이동(isPending)이 아니면 직접 옮김으로 기록 | I34: 없음 | J34: manualMoves, newBookmarks | K34: 순서만 바뀐 이동은 기록하지 않음. 알림이 동시에 여러 개 와도 순서대로 처리(update 사용) | L34: F07 | M34: #6
A35: 저장 항목 | B35: 팀원 B | C35: N34 | D35: background.js | E35: onRemoved 처리 | F35: (id, removeInfo) | G35: 없음 | H35: 삭제된 북마크(폴더면 안의 북마크까지) ID를 서비스 워커가 쓰는 항목에서 정리 | I35: 없음 | J35: manualMoves, newBookmarks | K35: 새 탭이 쓰는 항목은 cleanupMissing이 정리 | L35: F01 | M35: #6
A36: 세부 폴더 | B36: 팀원 C | C36: N35 | D36: topic.js | E36: suggestSubfolders(folderItems) | F36: 폴더 안 북마크 | G36: [{ word, items }] | H36: 제목에 반복되는 주제 단어(북마크 3개 이상, 사이트 2곳 이상)로 세부 폴더 제안 | I36: 없음 | J36: 없음 | K36: 조건에 맞는 단어가 없으면 빈 배열 | L36: F16 | M36: #12
A37: 드래그 이동 | B37: 팀원 D | C37: N36 | D37: dnd.js | E37: initDnd(container) | F37: 화면 영역 | G37: 없음 | H37: SortableJS로 순서 바꾸기, 폴더 위에 놓기는 직접 구현 | I37: 이동 | J37: 없음 (직접 옮김은 서비스 워커가 기록) | K37: 놓을 수 없는 곳이면 원래 자리로. 같은 폴더 안에서 뒤쪽으로 옮길 때는 순서 번호에 1을 더함 | L37: F17 | M37: #19
A38: 새 북마크 정리 | B38: 팀원 C | C38: N37 | D38: plan.js | E38: suggestNewFolders(tree, stored, categories) | F38: 북마크 목록, 저장 항목, 분류표 | G38: [{ name, items }] | H38: 폴더 밖에 같은 카테고리가 3개 이상 모였고 우리가 만든 폴더 수가 상한 미만이면 새 폴더를 제안 | I38: 없음 | J38: 없음 | K38: 같은 이름의 폴더가 이미 있으면 제안하지 않음. 상한에 찼으면 빈 배열 | L38: F10 | M38: #11
A39: 정리 카드 | B39: 팀원 A | C39: N38 | D39: store.js | E39: setFirstCard(value) | F39: "pending" | "done" | "later" | G39: 없음 | H39: 첫 정리 카드 상태를 바꿈 | I39: 없음 | J39: state | K39: 새 탭만 호출 | L39: F06 | M39: #3
A40: 새 북마크 정리 | B40: 팀원 A | C40: N39 | D40: store.js | E40: markHandledNew(ids) | F40: 북마크 ID 배열 | G40: 없음 | H40: '그대로 두기'로 둔 새 북마크를 기록 | I40: 없음 | J40: handledNew | K40: 새 탭만 호출 (applyPlan이 부름) | L40: F10 | M40: #3
...

Sheet 참고_저장 항목
A1: 도메인 | B1: 담당(안) | C1: 키 | D1: 형태 | E1: 뜻 | F1: 쓰는 쪽 | G1: 읽는 쪽 | H1: 관련 기능
A2: 고정(독) | B2: 팀원 A | C2: pinned | D2: [북마크ID, …] | E2: 화면 아래의 고정됨(독)에 고정한 북마크 (표시 순서대로, 최대 8개) | F2: 새 탭 | G2: 새 탭 | H2: F08, F09
A3: 재발견 | B3: 팀원 A | C3: lastOpenedByUs | D3: { 북마크ID: 시각(ms) } | E3: 우리 새 탭에서 연 시각 | F3: 새 탭 | G3: 새 탭 | H3: F02, F04, F09
A4: 재발견 | B4: 팀원 A | C4: dismissed | D4: { 북마크ID: 시각(ms) } | E4: "이제 안 봐도 됨"을 누른 북마크 | F4: 새 탭 | G4: 새 탭 | H4: F04
A5: 직접 옮김 감지 | B5: 팀원 B | C5: manualMoves | D5: { 북마크ID: 시각(ms) } | E5: 사용자가 직접 옮긴 북마크 (다음 정리에서 제외) | F5: 서비스 워커 | G5: 새 탭 | H5: F05, F07, F15, F17
A6: 새 북마크 정리 | B6: 팀원 B | C6: newBookmarks | D6: [북마크ID, …] | E6: 폴더 밖에 새로 저장되고 아직 옮기지 않은 북마크 | F6: 서비스 워커 | G6: 새 탭 | H6: F10
A7: 새 북마크 정리 | B7: 팀원 A | C7: handledNew | D7: [북마크ID, …] | E7: 새 북마크 중 [정리하기]에서 '그대로 두기'로 둔 것. "새로" 표시와 버튼 개수 = newBookmarks에서 handledNew를 뺀 것 | F7: 새 탭 | G7: 새 탭 | H7: F10
A8: 직접 옮김 감지 | B8: 팀원 A | C8: pendingMoves | D8: { 북마크ID: { toParentId, at } } | E8: 우리 정리가 옮기는 북마크의 목적지와 시각 (1분 뒤 만료) | F8: 새 탭 | G8: 서비스 워커 | H8: F07, F13
A9: 되돌리기·정리 기록 | B9: 팀원 A | C9: history | D9: [{ id, at, type, createdFolderIds, moves: [{bookmarkId, title, fromParentId, fromIndex, toParentId}], fromOrder: { 원래 폴더ID: [북마크ID, …] }, skipped, undoneAt }] | E9: 정리 기록. type은 "first"(첫 정리) 또는 "new"(새 북마크 정리). fromOrder는 정리 직전 원래 폴더의 전체 순서(되돌릴 때 사용) | F9: 새 탭 | G9: 새 탭 | H9: F07, F10, F13
A10: 정리 카드 | B10: 팀원 A | C10: state | D10: { firstCard: "pending" | "done" | "later" } | E10: 첫 정리 카드 상태 (값이 없으면 pending으로 봄) | F10: 새 탭 | G10: 새 탭 | H10: F06, F09
A12: 참고 | C12: 한 키는 한쪽(새 탭 또는 서비스 워커)만 쓴다. 두 쪽이 같은 키를 동시에 고치면 한쪽 값이 사라지기 때문이다(실행 확인: 120번 쓴 것 중 91개만 남음). 새 탭을 두 개 열어 놓고 같은 순간에 조작하는 경우는 드물어 따로 막지 않는다. 모두 chrome.storage.local에 저장하며 이 PC에만 남는다. 북마크 ID도 이 PC 안에서만 유효하다. 북마크 원본(제목·주소)은 저장하지 않고, history의 title만 기록 화면 표시용으로 남긴다.

Sheet 파일별 역할
A1: 파일 | B1: 이 파일이 하는 일 | C1: 들어 있는 도메인 | D1: 담당(안) | E1: 내부 함수 수 | F1: 작성 방식 (프로토타입은 참고만) | G1: 이슈
A2: manifest.json | B2: 확장 프로그램의 설정 파일. 필요한 권한, 새 탭 바꾸기, 서비스 워커를 등록한다 | C2: 확장 프로그램 설정 | D2: 팀원 A | E2: =COUNTIF('API_내부 함수'!$D:$D,"manifest.json") -> 0 | F2: 새로 작성 | G2: #1
A3: background.js | B3: 서비스 워커. 새 탭이 닫혀 있어도 북마크가 새로 저장·이동·삭제되는 것을 받아 저장소에 기록한다 | C3: 새 북마크 정리, 직접 옮김 감지, 저장 항목 | D3: 팀원 B | E3: =COUNTIF('API_내부 함수'!$D:$D,"background.js") -> 3 | F3: 새로 작성 (프로토타입에 검증된 참고 코드 있음) | G3: #6
A4: js/store.js | B4: 저장 항목을 읽고 쓰는 통로. 고정 목록, 연 시각, 정리 기록, '옮기는 중' 표시 등 모든 저장이 이 파일을 거친다 | C4: 저장 항목, 고정(독), 재발견, 직접 옮김 감지, 되돌리기·정리 기록 | D4: 팀원 A | E4: =COUNTIF('API_내부 함수'!$D:$D,"store.js") -> 12 | F4: 새로 작성 (프로토타입에 검증된 참고 코드 있음) | G4: #3
A5: js/bookmarks.js | B5: 크롬 북마크를 읽고 바꾸는 통로. 전체 읽기, 폴더 만들기·이름 바꾸기·삭제, 북마크 옮기기·열기, 파비콘 | C5: 북마크 동기화, 앱 폴더, 정리 적용, 앱 표시·열기 | D5: 팀원 A | E5: =COUNTIF('API_내부 함수'!$D:$D,"bookmarks.js") -> 7 | F5: 새로 작성 (프로토타입에 검증된 참고 코드 있음) | G5: #2
A6: js/organize.js | B6: 북마크를 실제로 바꾸는 정리 코드. 계획대로 옮기고 기록을 남기며, 기록을 보고 되돌린다 | C6: 정리 적용, 되돌리기·정리 기록 | D6: 팀원 A | E6: =COUNTIF('API_내부 함수'!$D:$D,"organize.js") -> 2 | F6: 새로 작성 (프로토타입에 검증된 참고 코드 있음) | G6: #4
A7: js/classify.js | B7: 북마크 하나를 카테고리에 넣는 규칙. 정답지로 정확도를 재고, 새 북마크의 추천 폴더를 정한다 (계산만 함) | C7: 분류 규칙, 새 북마크 정리 | D7: 팀원 B | E7: =COUNTIF('API_내부 함수'!$D:$D,"classify.js") -> 3 | F7: 새로 작성 (프로토타입에 검증된 참고 코드 있음) | G7: #7
A8: data/categories.json | B8: 사이트 분류표, 주소 끝 규칙, 제목 키워드, 분류하지 않는 사이트. 코드가 아니라 데이터라서 사이트를 추가할 때 이 파일과 category-definitions.md 10번만 고친다 | C8: 분류 규칙 | D8: 팀원 B | E8: =COUNTIF('API_내부 함수'!$D:$D,"categories.json") -> 0 | F8: 작성함 (v11, category-definitions.md 10번을 옮김) | G8: #10
A9: js/forgotten.js | B9: 마지막으로 연 시각을 정하고, 30일 넘게 안 연 북마크를 오래 안 연 순으로 고른다. 화면은 8개까지 보여 준다 (계산만 함) | C9: 재발견 | D9: 팀원 B | E9: =COUNTIF('API_내부 함수'!$D:$D,"forgotten.js") -> 2 | F9: 새로 작성 (프로토타입에 검증된 참고 코드 있음) | G9: #8
A10: js/plan.js | B10: 정리 대상을 고르고(북마크바 포함, 요즘 쓰는 북마크 제외) 폴더 계획을 세운다. 폴더를 못 만들면 고정 후보를, 새 북마크가 모이면 새 폴더를 제안한다 (계산만 함) | C10: 폴더 계획, 고정 제안, 새 북마크 정리 | D10: 팀원 C | E10: =COUNTIF('API_내부 함수'!$D:$D,"plan.js") -> 4 | F10: 새로 작성 (프로토타입에 검증된 참고 코드 있음) | G10: #11
A11: js/topic.js | B11: 큰 폴더 안에서 반복되는 주제 단어를 찾아 세부 폴더를 제안한다 | C11: 세부 폴더 | D11: 팀원 C | E11: =COUNTIF('API_내부 함수'!$D:$D,"topic.js") -> 1 | F11: 새로 작성 | G11: #12
A12: js/render.js | B12: 화면의 시작점. 북마크·저장소 알림을 받아 전체를 다시 그리고, 화면 파일(view/*)의 그리기 함수를 부른다. 헤더, 날짜, 화면 아래의 고정됨(독), 모든 북마크는 직접 그린다 | C12: 화면 배치, 앱 표시·열기 | D12: 팀원 D | E12: =COUNTIF('API_내부 함수'!$D:$D,"render.js") -> 1 | F12: 새로 작성 | G12: #15
A13: newtab.html / newtab.css | B13: 새 탭 화면의 뼈대와 모양 | C13: 화면 배치 | D13: 팀원 D | E13: =COUNTIF('API_내부 함수'!$D:$D," newtab.css") -> 0 | F13: 새로 작성 | G13: #14
A14: js/search.js | B14: 웹 검색창(위쪽. 주소 판별, 기본 검색엔진 호출)과 북마크 검색(모든 북마크 영역의 검색창). 두 검색창은 연동하지 않는다 | C14: 웹 검색, 북마크 검색 | D14: 팀원 D | E14: =COUNTIF('API_내부 함수'!$D:$D,"search.js") -> 3 | F14: 새로 작성 (프로토타입에 검증된 참고 코드 있음) | G14: #18
A15: js/dnd.js | B15: 끌어서 폴더에 넣기와 순서 바꾸기 (SortableJS) | C15: 드래그 이동 | D15: 팀원 D | E15: =COUNTIF('API_내부 함수'!$D:$D,"dnd.js") -> 1 | F15: 새로 작성 | G15: #19
A16: js/view/cards.js | B16: 첫 정리 카드, 고정 제안 카드, 자세히 보기와 [정리하기] 창, 고정할 북마크 고르기 창. 고정 제안의 권한 요청 | C16: 정리 카드, 고정 제안(권한 요청), 새 북마크 정리(창) | D16: 팀원 D | E16: =COUNTIF('API_내부 함수'!$D:$D,"view/cards.js") -> 1 | F16: 새로 작성 | G16: #17
A17: js/view/folders.js | B17: 내 폴더 줄, 폴더 팝업, 폴더 만들기·이름 바꾸기·삭제, 우클릭 메뉴 | C17: 앱 폴더, 우클릭 이동 | D17: 팀원 C | E17: =COUNTIF('API_내부 함수'!$D:$D,"view/folders.js") -> 1 | F17: 새로 작성 | G17: #13
A18: js/view/forgottenFolder.js | B18: 잊고 있던 북마크 폴더와 팝업 (8개까지 표시) | C18: 재발견 | D18: 팀원 B | E18: =COUNTIF('API_내부 함수'!$D:$D,"view/forgottenFolder.js") -> 1 | F18: 새로 작성 | G18: #9
A19: js/view/history.js | B19: 정리 결과 안내([되돌리기])와 정리 기록 화면 | C19: 되돌리기·정리 기록 | D19: 팀원 A | E19: =COUNTIF('API_내부 함수'!$D:$D,"view/history.js") -> 1 | F19: 새로 작성 | G19: #5
A20: js/ui.js | B20: 모든 화면 파일이 함께 쓰는 공통 화면 조각. 앱 아이콘(색 타일 위의 파비콘, 없으면 첫 글자), 짧은 안내 문구, 선 아이콘 | C20: 앱 표시·열기, 화면 배치 | D20: 팀원 D | E20: =COUNTIF('API_내부 함수'!$D:$D,"ui.js") -> 3 | F20: 새로 작성 | G20: #16
